Workbook

Sheet Test Summary
A1: TenantEcom: manual and regression test summary
A2: Generated 2026-10-13 from docs/qa/tools. Figures recalculate as Status cells change.
A4: Portal | B4: Total cases | C4: Executed (Pass + Fail) | D4: Passed | E4: Failed | F4: Blocked | G4: Not Run | H4: Not Applicable | I4: Pass % | J4: Critical cases | K4: Smoke cases
A5: Super Admin | B5: =COUNTA('Super Admin'!A:A)-1 | C5: =D5+E5 | D5: =COUNTIF('Super Admin'!L:L,"Pass") | E5: =COUNTIF('Super Admin'!L:L,"Fail") | F5: =COUNTIF('Super Admin'!L:L,"Blocked") | G5: =COUNTIF('Super Admin'!L:L,"Not Run") | H5: =COUNTIF('Super Admin'!L:L,"Not Applicable") | I5: =IF(C5=0,0,D5/C5) | J5: =COUNTIF('Super Admin'!M:M,"Critical") | K5: =COUNTIF('Super Admin'!T:T,"Yes")
A6: Vendor CMS | B6: =COUNTA('Vendor CMS'!A:A)-1 | C6: =D6+E6 | D6: =COUNTIF('Vendor CMS'!L:L,"Pass") | E6: =COUNTIF('Vendor CMS'!L:L,"Fail") | F6: =COUNTIF('Vendor CMS'!L:L,"Blocked") | G6: =COUNTIF('Vendor CMS'!L:L,"Not Run") | H6: =COUNTIF('Vendor CMS'!L:L,"Not Applicable") | I6: =IF(C6=0,0,D6/C6) | J6: =COUNTIF('Vendor CMS'!M:M,"Critical") | K6: =COUNTIF('Vendor CMS'!T:T,"Yes")
A7: End-to-End Workflows | B7: =COUNTA('End-to-End Workflows'!A:A)-1 | C7: =D7+E7 | D7: =COUNTIF('End-to-End Workflows'!L:L,"Pass") | E7: =COUNTIF('End-to-End Workflows'!L:L,"Fail") | F7: =COUNTIF('End-to-End Workflows'!L:L,"Blocked") | G7: =COUNTIF('End-to-End Workflows'!L:L,"Not Run") | H7: =COUNTIF('End-to-End Workflows'!L:L,"Not Applicable") | I7: =IF(C7=0,0,D7/C7) | J7: =COUNTIF('End-to-End Workflows'!M:M,"Critical") | K7: =COUNTIF('End-to-End Workflows'!T:T,"Yes")
A8: All portals | B8: =SUM(B5:B7) | C8: =SUM(C5:C7) | D8: =SUM(D5:D7) | E8: =SUM(E5:E7) | F8: =SUM(F5:F7) | G8: =SUM(G5:G7) | H8: =SUM(H5:H7) | I8: =IF(C8=0,0,D8/C8) | J8: =SUM(J5:J7) | K8: =SUM(K5:K7)
A10: Coverage by module
A11: Module | B11: Portal | C11: Cases | D11: Passed | E11: Failed | F11: Blocked | G11: Not Run | H11: Pass % | I11: Critical | J11: Regression script
A12: SA-01 · Sign in and two-step verification | B12: Super Admin | C12: =COUNTIF('Super Admin'!C:C,A12) | D12: =COUNTIFS('Super Admin'!C:C,A12,'Super Admin'!L:L,"Pass") | E12: =COUNTIFS('Super Admin'!C:C,A12,'Super Admin'!L:L,"Fail") | F12: =COUNTIFS('Super Admin'!C:C,A12,'Super Admin'!L:L,"Blocked") | G12: =COUNTIFS('Super Admin'!C:C,A12,'Super Admin'!L:L,"Not Run") | H12: =IF((D12+E12)=0,0,D12/(D12+E12)) | I12: =COUNTIFS('Super Admin'!C:C,A12,'Super Admin'!M:M,"Critical") | J12: docs/qa/regression/super-admin/SA-01-sign-in.md
A13: SA-02 · Platform dashboard | B13: Super Admin | C13: =COUNTIF('Super Admin'!C:C,A13) | D13: =COUNTIFS('Super Admin'!C:C,A13,'Super Admin'!L:L,"Pass") | E13: =COUNTIFS('Super Admin'!C:C,A13,'Super Admin'!L:L,"Fail") | F13: =COUNTIFS('Super Admin'!C:C,A13,'Super Admin'!L:L,"Blocked") | G13: =COUNTIFS('Super Admin'!C:C,A13,'Super Admin'!L:L,"Not Run") | H13: =IF((D13+E13)=0,0,D13/(D13+E13)) | I13: =COUNTIFS('Super Admin'!C:C,A13,'Super Admin'!M:M,"Critical") | J13: docs/qa/regression/super-admin/SA-02-dashboard.md
A14: SA-03 · All vendors | B14: Super Admin | C14: =COUNTIF('Super Admin'!C:C,A14) | D14: =COUNTIFS('Super Admin'!C:C,A14,'Super Admin'!L:L,"Pass") | E14: =COUNTIFS('Super Admin'!C:C,A14,'Super Admin'!L:L,"Fail") | F14: =COUNTIFS('Super Admin'!C:C,A14,'Super Admin'!L:L,"Blocked") | G14: =COUNTIFS('Super Admin'!C:C,A14,'Super Admin'!L:L,"Not Run") | H14: =IF((D14+E14)=0,0,D14/(D14+E14)) | I14: =COUNTIFS('Super Admin'!C:C,A14,'Super Admin'!M:M,"Critical") | J14: docs/qa/regression/super-admin/SA-03-all-vendors.md
A15: SA-04 · New vendor (onboarding) | B15: Super Admin | C15: =COUNTIF('Super Admin'!C:C,A15) | D15: =COUNTIFS('Super Admin'!C:C,A15,'Super Admin'!L:L,"Pass") | E15: =COUNTIFS('Super Admin'!C:C,A15,'Super Admin'!L:L,"Fail") | F15: =COUNTIFS('Super Admin'!C:C,A15,'Super Admin'!L:L,"Blocked") | G15: =COUNTIFS('Super Admin'!C:C,A15,'Super Admin'!L:L,"Not Run") | H15: =IF((D15+E15)=0,0,D15/(D15+E15)) | I15: =COUNTIFS('Super Admin'!C:C,A15,'Super Admin'!M:M,"Critical") | J15: docs/qa/regression/super-admin/SA-04-new-vendor.md
A16: SA-05 · Vendor overview and store status | B16: Super Admin | C16: =COUNTIF('Super Admin'!C:C,A16) | D16: =COUNTIFS('Super Admin'!C:C,A16,'Super Admin'!L:L,"Pass") | E16: =COUNTIFS('Super Admin'!C:C,A16,'Super Admin'!L:L,"Fail") | F16: =COUNTIFS('Super Admin'!C:C,A16,'Super Admin'!L:L,"Blocked") | G16: =COUNTIFS('Super Admin'!C:C,A16,'Super Admin'!L:L,"Not Run") | H16: =IF((D16+E16)=0,0,D16/(D16+E16)) | I16: =COUNTIFS('Super Admin'!C:C,A16,'Super Admin'!M:M,"Critical") | J16: docs/qa/regression/super-admin/SA-05-vendor-overview.md
A17: SA-06 · Store sessions (Manage store, View as support) | B17: Super Admin | C17: =COUNTIF('Super Admin'!C:C,A17) | D17: =COUNTIFS('Super Admin'!C:C,A17,'Super Admin'!L:L,"Pass") | E17: =COUNTIFS('Super Admin'!C:C,A17,'Super Admin'!L:L,"Fail") | F17: =COUNTIFS('Super Admin'!C:C,A17,'Super Admin'!L:L,"Blocked") | G17: =COUNTIFS('Super Admin'!C:C,A17,'Super Admin'!L:L,"Not Run") | H17: =IF((D17+E17)=0,0,D17/(D17+E17)) | I17: =COUNTIFS('Super Admin'!C:C,A17,'Super Admin'!M:M,"Critical") | J17: docs/qa/regression/super-admin/SA-06-store-sessions.md
A18: SA-07 · Vendor features | B18: Super Admin | C18: =COUNTIF('Super Admin'!C:C,A18) | D18: =COUNTIFS('Super Admin'!C:C,A18,'Super Admin'!L:L,"Pass") | E18: =COUNTIFS('Super Admin'!C:C,A18,'Super Admin'!L:L,"Fail") | F18: =COUNTIFS('Super Admin'!C:C,A18,'Super Admin'!L:L,"Blocked") | G18: =COUNTIFS('Super Admin'!C:C,A18,'Super Admin'!L:L,"Not Run") | H18: =IF((D18+E18)=0,0,D18/(D18+E18)) | I18: =COUNTIFS('Super Admin'!C:C,A18,'Super Admin'!M:M,"Critical") | J18: docs/qa/regression/super-admin/SA-07-vendor-features.md
A19: SA-08 · Vendor connectors | B19: Super Admin | C19: =COUNTIF('Super Admin'!C:C,A19) | D19: =COUNTIFS('Super Admin'!C:C,A19,'Super Admin'!L:L,"Pass") | E19: =COUNTIFS('Super Admin'!C:C,A19,'Super Admin'!L:L,"Fail") | F19: =COUNTIFS('Super Admin'!C:C,A19,'Super Admin'!L:L,"Blocked") | G19: =COUNTIFS('Super Admin'!C:C,A19,'Super Admin'!L:L,"Not Run") | H19: =IF((D19+E19)=0,0,D19/(D19+E19)) | I19: =COUNTIFS('Super Admin'!C:C,A19,'Super Admin'!M:M,"Critical") | J19: docs/qa/regression/super-admin/SA-08-vendor-connectors.md
A20: SA-09 · Vendor domains | B20: Super Admin | C20: =COUNTIF('Super Admin'!C:C,A20) | D20: =COUNTIFS('Super Admin'!C:C,A20,'Super Admin'!L:L,"Pass") | E20: =COUNTIFS('Super Admin'!C:C,A20,'Super Admin'!L:L,"Fail") | F20: =COUNTIFS('Super Admin'!C:C,A20,'Super Admin'!L:L,"Blocked") | G20: =COUNTIFS('Super Admin'!C:C,A20,'Super Admin'!L:L,"Not Run") | H20: =IF((D20+E20)=0,0,D20/(D20+E20)) | I20: =COUNTIFS('Super Admin'!C:C,A20,'Super Admin'!M:M,"Critical") | J20: docs/qa/regression/super-admin/SA-09-vendor-domains.md
A21: SA-10 · Vendor billing | B21: Super Admin | C21: =COUNTIF('Super Admin'!C:C,A21) | D21: =COUNTIFS('Super Admin'!C:C,A21,'Super Admin'!L:L,"Pass") | E21: =COUNTIFS('Super Admin'!C:C,A21,'Super Admin'!L:L,"Fail") | F21: =COUNTIFS('Super Admin'!C:C,A21,'Super Admin'!L:L,"Blocked") | G21: =COUNTIFS('Super Admin'!C:C,A21,'Super Admin'!L:L,"Not Run") | H21: =IF((D21+E21)=0,0,D21/(D21+E21)) | I21: =COUNTIFS('Super Admin'!C:C,A21,'Super Admin'!M:M,"Critical") | J21: docs/qa/regression/super-admin/SA-10-vendor-billing.md
A22: SA-11 · Vendor staff | B22: Super Admin | C22: =COUNTIF('Super Admin'!C:C,A22) | D22: =COUNTIFS('Super Admin'!C:C,A22,'Super Admin'!L:L,"Pass") | E22: =COUNTIFS('Super Admin'!C:C,A22,'Super Admin'!L:L,"Fail") | F22: =COUNTIFS('Super Admin'!C:C,A22,'Super Admin'!L:L,"Blocked") | G22: =COUNTIFS('Super Admin'!C:C,A22,'Super Admin'!L:L,"Not Run") | H22: =IF((D22+E22)=0,0,D22/(D22+E22)) | I22: =COUNTIFS('Super Admin'!C:C,A22,'Super Admin'!M:M,"Critical") | J22: docs/qa/regression/super-admin/SA-11-vendor-staff.md
A23: SA-12 · Plans | B23: Super Admin | C23: =COUNTIF('Super Admin'!C:C,A23) | D23: =COUNTIFS('Super Admin'!C:C,A23,'Super Admin'!L:L,"Pass") | E23: =COUNTIFS('Super Admin'!C:C,A23,'Super Admin'!L:L,"Fail") | F23: =COUNTIFS('Super Admin'!C:C,A23,'Super Admin'!L:L,"Blocked") | G23: =COUNTIFS('Super Admin'!C:C,A23,'Super Admin'!L:L,"Not Run") | H23: =IF((D23+E23)=0,0,D23/(D23+E23)) | I23: =COUNTIFS('Super Admin'!C:C,A23,'Super Admin'!M:M,"Critical") | J23: docs/qa/regression/super-admin/SA-12-plans.md
... A26: SA-15 · Platform permissions and isolation | B26: Super Admin | C26: =COUNTIF('Super Admin'!C:C,A26) | D26: =COUNTIFS('Super Admin'!C:C,A26,'Super Admin'!L:L,"Pass") | E26: =COUNTIFS('Super Admin'!C:C,A26,'Super Admin'!L:L,"Fail") | F26: =COUNTIFS('Super Admin'!C:C,A26,'Super Admin'!L:L,"Blocked") | G26: =COUNTIFS('Super Admin'!C:C,A26,'Super Admin'!L:L,"Not Run") | H26: =IF((D26+E26)=0,0,D26/(D26+E26)) | I26: =COUNTIFS('Super Admin'!C:C,A26,'Super Admin'!M:M,"Critical") | J26: docs/qa/regression/super-admin/SA-15-permissions.md
A27: VC-01 · Sign in, first password and session | B27: Vendor CMS | C27: =COUNTIF('Vendor CMS'!C:C,A27) | D27: =COUNTIFS('Vendor CMS'!C:C,A27,'Vendor CMS'!L:L,"Pass") | E27: =COUNTIFS('Vendor CMS'!C:C,A27,'Vendor CMS'!L:L,"Fail") | F27: =COUNTIFS('Vendor CMS'!C:C,A27,'Vendor CMS'!L:L,"Blocked") | G27: =COUNTIFS('Vendor CMS'!C:C,A27,'Vendor CMS'!L:L,"Not Run") | H27: =IF((D27+E27)=0,0,D27/(D27+E27)) | I27: =COUNTIFS('Vendor CMS'!C:C,A27,'Vendor CMS'!M:M,"Critical") | J27: docs/qa/regression/vendor-cms/VC-01-sign-in.md
A28: VC-02 · Store dashboard and navigation | B28: Vendor CMS | C28: =COUNTIF('Vendor CMS'!C:C,A28) | D28: =COUNTIFS('Vendor CMS'!C:C,A28,'Vendor CMS'!L:L,"Pass") | E28: =COUNTIFS('Vendor CMS'!C:C,A28,'Vendor CMS'!L:L,"Fail") | F28: =COUNTIFS('Vendor CMS'!C:C,A28,'Vendor CMS'!L:L,"Blocked") | G28: =COUNTIFS('Vendor CMS'!C:C,A28,'Vendor CMS'!L:L,"Not Run") | H28: =IF((D28+E28)=0,0,D28/(D28+E28)) | I28: =COUNTIFS('Vendor CMS'!C:C,A28,'Vendor CMS'!M:M,"Critical") | J28: docs/qa/regression/vendor-cms/VC-02-dashboard.md
A29: VC-03 · Store settings | B29: Vendor CMS | C29: =COUNTIF('Vendor CMS'!C:C,A29) | D29: =COUNTIFS('Vendor CMS'!C:C,A29,'Vendor CMS'!L:L,"Pass") | E29: =COUNTIFS('Vendor CMS'!C:C,A29,'Vendor CMS'!L:L,"Fail") | F29: =COUNTIFS('Vendor CMS'!C:C,A29,'Vendor CMS'!L:L,"Blocked") | G29: =COUNTIFS('Vendor CMS'!C:C,A29,'Vendor CMS'!L:L,"Not Run") | H29: =IF((D29+E29)=0,0,D29/(D29+E29)) | I29: =COUNTIFS('Vendor CMS'!C:C,A29,'Vendor CMS'!M:M,"Critical") | J29: docs/qa/regression/vendor-cms/VC-03-store-settings.md
A30: VC-04 · Products and product editor | B30: Vendor CMS | C30: =COUNTIF('Vendor CMS'!C:C,A30) | D30: =COUNTIFS('Vendor CMS'!C:C,A30,'Vendor CMS'!L:L,"Pass") | E30: =COUNTIFS('Vendor CMS'!C:C,A30,'Vendor CMS'!L:L,"Fail") | F30: =COUNTIFS('Vendor CMS'!C:C,A30,'Vendor CMS'!L:L,"Blocked") | G30: =COUNTIFS('Vendor CMS'!C:C,A30,'Vendor CMS'!L:L,"Not Run") | H30: =IF((D30+E30)=0,0,D30/(D30+E30)) | I30: =COUNTIFS('Vendor CMS'!C:C,A30,'Vendor CMS'!M:M,"Critical") | J30: docs/qa/regression/vendor-cms/VC-04-products.md
A31: VC-05 · Categories | B31: Vendor CMS | C31: =COUNTIF('Vendor CMS'!C:C,A31) | D31: =COUNTIFS('Vendor CMS'!C:C,A31,'Vendor CMS'!L:L,"Pass") | E31: =COUNTIFS('Vendor CMS'!C:C,A31,'Vendor CMS'!L:L,"Fail") | F31: =COUNTIFS('Vendor CMS'!C:C,A31,'Vendor CMS'!L:L,"Blocked") | G31: =COUNTIFS('Vendor CMS'!C:C,A31,'Vendor CMS'!L:L,"Not Run") | H31: =IF((D31+E31)=0,0,D31/(D31+E31)) | I31: =COUNTIFS('Vendor CMS'!C:C,A31,'Vendor CMS'!M:M,"Critical") | J31: docs/qa/regression/vendor-cms/VC-05-categories.md
A32: VC-06 · Attribute sets | B32: Vendor CMS | C32: =COUNTIF('Vendor CMS'!C:C,A32) | D32: =COUNTIFS('Vendor CMS'!C:C,A32,'Vendor CMS'!L:L,"Pass") | E32: =COUNTIFS('Vendor CMS'!C:C,A32,'Vendor CMS'!L:L,"Fail") | F32: =COUNTIFS('Vendor CMS'!C:C,A32,'Vendor CMS'!L:L,"Blocked") | G32: =COUNTIFS('Vendor CMS'!C:C,A32,'Vendor CMS'!L:L,"Not Run") | H32: =IF((D32+E32)=0,0,D32/(D32+E32)) | I32: =COUNTIFS('Vendor CMS'!C:C,A32,'Vendor CMS'!M:M,"Critical") | J32: docs/qa/regression/vendor-cms/VC-06-attribute-sets.md
A33: VC-07 · Brands, Documents and Variants | B33: Vendor CMS | C33: =COUNTIF('Vendor CMS'!C:C,A33) | D33: =COUNTIFS('Vendor CMS'!C:C,A33,'Vendor CMS'!L:L,"Pass") | E33: =COUNTIFS('Vendor CMS'!C:C,A33,'Vendor CMS'!L:L,"Fail") | F33: =COUNTIFS('Vendor CMS'!C:C,A33,'Vendor CMS'!L:L,"Blocked") | G33: =COUNTIFS('Vendor CMS'!C:C,A33,'Vendor CMS'!L:L,"Not Run") | H33: =IF((D33+E33)=0,0,D33/(D33+E33)) | I33: =COUNTIFS('Vendor CMS'!C:C,A33,'Vendor CMS'!M:M,"Critical") | J33: docs/qa/regression/vendor-cms/VC-07-brands-documents.md
A34: VC-08 · Import and export | B34: Vendor CMS | C34: =COUNTIF('Vendor CMS'!C:C,A34) | D34: =COUNTIFS('Vendor CMS'!C:C,A34,'Vendor CMS'!L:L,"Pass") | E34: =COUNTIFS('Vendor CMS'!C:C,A34,'Vendor CMS'!L:L,"Fail") | F34: =COUNTIFS('Vendor CMS'!C:C,A34,'Vendor CMS'!L:L,"Blocked") | G34: =COUNTIFS('Vendor CMS'!C:C,A34,'Vendor CMS'!L:L,"Not Run") | H34: =IF((D34+E34)=0,0,D34/(D34+E34)) | I34: =COUNTIFS('Vendor CMS'!C:C,A34,'Vendor CMS'!M:M,"Critical") | J34: docs/qa/regression/vendor-cms/VC-08-import.md
A35: VC-09 · Media library | B35: Vendor CMS | C35: =COUNTIF('Vendor CMS'!C:C,A35) | D35: =COUNTIFS('Vendor CMS'!C:C,A35,'Vendor CMS'!L:L,"Pass") | E35: =COUNTIFS('Vendor CMS'!C:C,A35,'Vendor CMS'!L:L,"Fail") | F35: =COUNTIFS('Vendor CMS'!C:C,A35,'Vendor CMS'!L:L,"Blocked") | G35: =COUNTIFS('Vendor CMS'!C:C,A35,'Vendor CMS'!L:L,"Not Run") | H35: =IF((D35+E35)=0,0,D35/(D35+E35)) | I35: =COUNTIFS('Vendor CMS'!C:C,A35,'Vendor CMS'!M:M,"Critical") | J35: docs/qa/regression/vendor-cms/VC-09-media.md
A36: VC-10 · Orders and order detail | B36: Vendor CMS | C36: =COUNTIF('Vendor CMS'!C:C,A36) | D36: =COUNTIFS('Vendor CMS'!C:C,A36,'Vendor CMS'!L:L,"Pass") | E36: =COUNTIFS('Vendor CMS'!C:C,A36,'Vendor CMS'!L:L,"Fail") | F36: =COUNTIFS('Vendor CMS'!C:C,A36,'Vendor CMS'!L:L,"Blocked") | G36: =COUNTIFS('Vendor CMS'!C:C,A36,'Vendor CMS'!L:L,"Not Run") | H36: =IF((D36+E36)=0,0,D36/(D36+E36)) | I36: =COUNTIFS('Vendor CMS'!C:C,A36,'Vendor CMS'!M:M,"Critical") | J36: docs/qa/regression/vendor-cms/VC-10-orders.md
A37: VC-11 · Returns | B37: Vendor CMS | C37: =COUNTIF('Vendor CMS'!C:C,A37) | D37: =COUNTIFS('Vendor CMS'!C:C,A37,'Vendor CMS'!L:L,"Pass") | E37: =COUNTIFS('Vendor CMS'!C:C,A37,'Vendor CMS'!L:L,"Fail") | F37: =COUNTIFS('Vendor CMS'!C:C,A37,'Vendor CMS'!L:L,"Blocked") | G37: =COUNTIFS('Vendor CMS'!C:C,A37,'Vendor CMS'!L:L,"Not Run") | H37: =IF((D37+E37)=0,0,D37/(D37+E37)) | I37: =COUNTIFS('Vendor CMS'!C:C,A37,'Vendor CMS'!M:M,"Critical") | J37: docs/qa/regression/vendor-cms/VC-11-returns.md
A38: VC-12 · Customers and privacy requests | B38: Vendor CMS | C38: =COUNTIF('Vendor CMS'!C:C,A38) | D38: =COUNTIFS('Vendor CMS'!C:C,A38,'Vendor CMS'!L:L,"Pass") | E38: =COUNTIFS('Vendor CMS'!C:C,A38,'Vendor CMS'!L:L,"Fail") | F38: =COUNTIFS('Vendor CMS'!C:C,A38,'Vendor CMS'!L:L,"Blocked") | G38: =COUNTIFS('Vendor CMS'!C:C,A38,'Vendor CMS'!L:L,"Not Run") | H38: =IF((D38+E38)=0,0,D38/(D38+E38)) | I38: =COUNTIFS('Vendor CMS'!C:C,A38,'Vendor CMS'!M:M,"Critical") | J38: docs/qa/regression/vendor-cms/VC-12-customers.md
... A55: VC-29 · Reports | B55: Vendor CMS | C55: =COUNTIF('Vendor CMS'!C:C,A55) | D55: =COUNTIFS('Vendor CMS'!C:C,A55,'Vendor CMS'!L:L,"Pass") | E55: =COUNTIFS('Vendor CMS'!C:C,A55,'Vendor CMS'!L:L,"Fail") | F55: =COUNTIFS('Vendor CMS'!C:C,A55,'Vendor CMS'!L:L,"Blocked") | G55: =COUNTIFS('Vendor CMS'!C:C,A55,'Vendor CMS'!L:L,"Not Run") | H55: =IF((D55+E55)=0,0,D55/(D55+E55)) | I55: =COUNTIFS('Vendor CMS'!C:C,A55,'Vendor CMS'!M:M,"Critical") | J55: docs/qa/regression/vendor-cms/VC-29-reports.md
A56: E2E-01 · Vendor onboarding to first store preview | B56: End-to-End | C56: =COUNTIF('End-to-End Workflows'!C:C,A56) | D56: =COUNTIFS('End-to-End Workflows'!C:C,A56,'End-to-End Workflows'!L:L,"Pass") | E56: =COUNTIFS('End-to-End Workflows'!C:C,A56,'End-to-End Workflows'!L:L,"Fail") | F56: =COUNTIFS('End-to-End Workflows'!C:C,A56,'End-to-End Workflows'!L:L,"Blocked") | G56: =COUNTIFS('End-to-End Workflows'!C:C,A56,'End-to-End Workflows'!L:L,"Not Run") | H56: =IF((D56+E56)=0,0,D56/(D56+E56)) | I56: =COUNTIFS('End-to-End Workflows'!C:C,A56,'End-to-End Workflows'!M:M,"Critical") | J56: docs/qa/regression/e2e/E2E-01-onboarding.md
A57: E2E-02 · Feature switches across portals | B57: End-to-End | C57: =COUNTIF('End-to-End Workflows'!C:C,A57) | D57: =COUNTIFS('End-to-End Workflows'!C:C,A57,'End-to-End Workflows'!L:L,"Pass") | E57: =COUNTIFS('End-to-End Workflows'!C:C,A57,'End-to-End Workflows'!L:L,"Fail") | F57: =COUNTIFS('End-to-End Workflows'!C:C,A57,'End-to-End Workflows'!L:L,"Blocked") | G57: =COUNTIFS('End-to-End Workflows'!C:C,A57,'End-to-End Workflows'!L:L,"Not Run") | H57: =IF((D57+E57)=0,0,D57/(D57+E57)) | I57: =COUNTIFS('End-to-End Workflows'!C:C,A57,'End-to-End Workflows'!M:M,"Critical") | J57: docs/qa/regression/e2e/E2E-02-features.md
A58: E2E-03 · Catalogue to storefront | B58: End-to-End | C58: =COUNTIF('End-to-End Workflows'!C:C,A58) | D58: =COUNTIFS('End-to-End Workflows'!C:C,A58,'End-to-End Workflows'!L:L,"Pass") | E58: =COUNTIFS('End-to-End Workflows'!C:C,A58,'End-to-End Workflows'!L:L,"Fail") | F58: =COUNTIFS('End-to-End Workflows'!C:C,A58,'End-to-End Workflows'!L:L,"Blocked") | G58: =COUNTIFS('End-to-End Workflows'!C:C,A58,'End-to-End Workflows'!L:L,"Not Run") | H58: =IF((D58+E58)=0,0,D58/(D58+E58)) | I58: =COUNTIFS('End-to-End Workflows'!C:C,A58,'End-to-End Workflows'!M:M,"Critical") | J58: docs/qa/regression/e2e/E2E-03-catalogue.md
A59: E2E-04 · Order to cash (COD) | B59: End-to-End | C59: =COUNTIF('End-to-End Workflows'!C:C,A59) | D59: =COUNTIFS('End-to-End Workflows'!C:C,A59,'End-to-End Workflows'!L:L,"Pass") | E59: =COUNTIFS('End-to-End Workflows'!C:C,A59,'End-to-End Workflows'!L:L,"Fail") | F59: =COUNTIFS('End-to-End Workflows'!C:C,A59,'End-to-End Workflows'!L:L,"Blocked") | G59: =COUNTIFS('End-to-End Workflows'!C:C,A59,'End-to-End Workflows'!L:L,"Not Run") | H59: =IF((D59+E59)=0,0,D59/(D59+E59)) | I59: =COUNTIFS('End-to-End Workflows'!C:C,A59,'End-to-End Workflows'!M:M,"Critical") | J59: docs/qa/regression/e2e/E2E-04-order-to-cash.md
A60: E2E-05 · Schemes and coupons to checkout | B60: End-to-End | C60: =COUNTIF('End-to-End Workflows'!C:C,A60) | D60: =COUNTIFS('End-to-End Workflows'!C:C,A60,'End-to-End Workflows'!L:L,"Pass") | E60: =COUNTIFS('End-to-End Workflows'!C:C,A60,'End-to-End Workflows'!L:L,"Fail") | F60: =COUNTIFS('End-to-End Workflows'!C:C,A60,'End-to-End Workflows'!L:L,"Blocked") | G60: =COUNTIFS('End-to-End Workflows'!C:C,A60,'End-to-End Workflows'!L:L,"Not Run") | H60: =IF((D60+E60)=0,0,D60/(D60+E60)) | I60: =COUNTIFS('End-to-End Workflows'!C:C,A60,'End-to-End Workflows'!M:M,"Critical") | J60: docs/qa/regression/e2e/E2E-05-offers.md
...

Sheet Vendor CMS
A1: Test Case ID | B1: Application/Portal | C1: Module Name | D1: Submodule/Feature | E1: Functionality | F1: Test Scenario | G1: Preconditions | H1: Test Data | I1: Step-by-Step Instructions | J1: Expected Result | K1: Actual Result | L1: Status | M1: Priority | N1: Test Type | O1: Executed By | P1: Execution Date | Q1: Defect/Bug ID | R1: Remarks/Additional Notes | S1: Role | T1: Smoke Run | U1: Regression Script
A2: VC-01-001 | B2: Vendor CMS | C2: VC-01 · Sign in, first password and session | D2: First password | E2: Short password refused | F2: The set-password page refuses passwords under 10 characters. | G2: Owner invite link open (private window) | H2: Password "Short12" | I2: 1. Type the short password in New Password and Confirm Password 2. Save 3. Verify the expected result. | J2: Refused with the minimum length message; the account stays without a password. | L2: Not Run | M2: High | N2: Validation | R2: Also: Boundary | S2: Store owner | T2: No | U2: docs/qa/regression/vendor-cms/VC-01-sign-in.md
A3: VC-01-002 | B3: Vendor CMS | C3: VC-01 · Sign in, first password and session | D3: First password | E3: Mismatch | F3: New and confirm password must match. | G3: Invite link open | H3: "HomeOrbit@2026" and "HomeOrbit@2027" | I3: 1. Type two different passwords 2. Save 3. Verify the expected result. | J3: Refused with a "passwords do not match" message. | L3: Not Run | M3: Medium | N3: Validation | S3: Store owner | T3: No | U3: docs/qa/regression/vendor-cms/VC-01-sign-in.md
A4: VC-01-003 | B4: Vendor CMS | C4: VC-01 · Sign in, first password and session | D4: First password | E4: Set password and land on dashboard | F4: A valid password signs the owner in. | G4: Invite link open | H4: Password "HomeOrbit@2026" | I4: 1. Type it twice 2. Save 3. Verify the expected result. | J4: Signed in at the store dashboard: greeting, today's date, Home Orbit, View store and Add product. | L4: Not Run | M4: Critical | N4: Functional | S4: Store owner | T4: Yes | U4: docs/qa/regression/vendor-cms/VC-01-sign-in.md
A5: VC-01-004 | B5: Vendor CMS | C5: VC-01 · Sign in, first password and session | D5: First password | E5: Link works once | F5: An invite link cannot be reused. | G5: Password already set with the link | H5: Same link | I5: 1. Open the same invite link again 2. Verify the expected result. | J5: The link is refused as used or expired. | L5: Not Run | M5: High | N5: Security/Permissions | S5: Store owner | T5: No | U5: docs/qa/regression/vendor-cms/VC-01-sign-in.md
A6: VC-01-005 | B6: Vendor CMS | C6: VC-01 · Sign in, first password and session | D6: Sign in | E6: Owner signs in without a code | F6: Two-step is optional for store staff. | G6: Owner has not set up two-step | H6: Owner email and password | I6: 1. Sign out 2. Sign in with email and password 3. Verify the expected result. | J6: The dashboard opens without a code step. | L6: Not Run | M6: High | N6: Functional | S6: Store owner | T6: No | U6: docs/qa/regression/vendor-cms/VC-01-sign-in.md
A7: VC-01-006 | B7: Vendor CMS | C7: VC-01 · Sign in, first password and session | D7: Sign in | E7: Optional two-step | F7: A store owner can turn on two-step and is then asked for the code. | G7: Owner signed in | H7: An authenticator app | I7: 1. Open your account (top bar name) 2. Set up two-step sign-in with the app 3. Sign out and in 4. Verify the expected result. | J7: Step 2 of 2 asks for the code; turning it off again is possible for store staff. | L7: Not Run | M7: Medium | N7: Security/Permissions | S7: Store owner | T7: No | U7: docs/qa/regression/vendor-cms/VC-01-sign-in.md
A8: VC-01-007 | B8: Vendor CMS | C8: VC-01 · Sign in, first password and session | D8: Sign in | E8: Wrong password | F8: A wrong password is refused. | G8: Signed out | H8: Wrong password | I8: 1. Sign in with the wrong password 2. Verify the expected result. | J8: "The email or password provided is incorrect." | L8: Not Run | M8: High | N8: Negative | S8: Store owner | T8: No | U8: docs/qa/regression/vendor-cms/VC-01-sign-in.md
A9: VC-02-001 | B9: Vendor CMS | C9: VC-02 · Store dashboard and navigation | D9: Header | E9: Greeting and actions | F9: The dashboard header matches the wireframe. | G9: Signed in as Home Orbit's owner (or super admin with Manage store on Home Orbit) | H9: — | I9: 1. Open http://localhost:3000/admin 2. Verify the expected result. | J9: "Good morning/afternoon/evening", today's date and Home Orbit, Import CSV (or View store) and Add product; "Your store isn't live yet" while a draft. | K9: "Good morning, Platform", Sat 10 Oct · Home Orbit, Import CSV, Add product, "Your store isn't live yet…"; figures Orders today 1, To ship 8, New enquiries 1. | L9: Pass | M9: High | N9: UI/UX | O9: Claude (Claude in Chrome) | P9: 2026-10-10 | R9: Run as super admin with Manage store. | S9: Store owner | T9: Yes | U9: docs/qa/regression/vendor-cms/VC-02-dashboard.md
A10: VC-02-002 | B10: Vendor CMS | C10: VC-02 · Store dashboard and navigation | D10: Menu | E10: Groups and plan meter | F10: The menu has the store groups and the plan usage. | G10: Signed in as Home Orbit's owner (or super admin with Manage store on Home Orbit) | H10: — | I10: 1. Read the left menu 2. Verify the expected result. | J10: Dashboard, Catalog, Sales, Marketing, Content, Store, Insights; Products 110 / 500 and the plan at the foot; no Vendors or Plans. | K10: Menu: Dashboard; Catalog; Sales; Marketing; Content; Store; Insights; Products 110 / 500 Starter plan; no Vendors or Plans. | L10: Pass | M10: High | N10: UI/UX | O10: Claude (Claude in Chrome) | P10: 2026-10-10 | R10: Also: Security/Permissions | S10: Store owner | T10: Yes | U10: docs/qa/regression/vendor-cms/VC-02-dashboard.md
A11: VC-02-003 | B11: Vendor CMS | C11: VC-02 · Store dashboard and navigation | D11: Menu | E11: Collapse persists | F11: The collapsed menu stays collapsed after reload. | G11: Signed in as Home Orbit's owner (or super admin with Manage store on Home Orbit) | H11: — | I11: 1. Press the collapse button at the bottom of the menu 2. Reload 3. Verify the expected result. | J11: The menu shows icons only (names on hover) and stays collapsed after reload. | L11: Not Run | M11: Low | N11: Data persistence | R11: Also: UI/UX | S11: Store owner | T11: No | U11: docs/qa/regression/vendor-cms/VC-02-dashboard.md
A12: VC-02-004 | B12: Vendor CMS | C12: VC-02 · Store dashboard and navigation | D12: Top bar | E12: Search with Ctrl K | F12: The top bar search jumps to products and other records. | G12: Signed in as Home Orbit's owner (or super admin with Manage store on Home Orbit) | H12: Search "soap" | I12: 1. Press Ctrl K 2. Type soap 3. Press Enter 4. Verify the expected result. | J12: Products opens filtered to soap dishes; arrow keys could pick Enquiries or Pages instead. | L12: Not Run | M12: Medium | N12: Functional | S12: Store owner | T12: No | U12: docs/qa/regression/vendor-cms/VC-02-dashboard.md
A13: VC-02-005 | B13: Vendor CMS | C13: VC-02 · Store dashboard and navigation | D13: Top bar | E13: Enquiry bell | F13: The bell counts new enquiries. | G13: Signed in as Home Orbit's owner (or super admin with Manage store on Home Orbit); new enquiries exist | H13: — | I13: 1. Read the bell number 2. Compare with Enquiries → New 3. Verify the expected result. | J13: The numbers match; the bell opens the inbox. | L13: Not Run | M13: Medium | N13: Integration | S13: Store owner | T13: No | U13: docs/qa/regression/vendor-cms/VC-02-dashboard.md
A14: VC-02-006 | B14: Vendor CMS | C14: VC-02 · Store dashboard and navigation | D14: Checklist | E14: Launch checklist | F14: The checklist shows the wireframe steps with Open links. | G14: Signed in as Home Orbit's owner (or super admin with Manage store on Home Orbit) | H14: — | I14: 1. Read the Launch checklist 2. Press Open on a step to do 3. Verify the expected result. | J14: Store name and logo, GST details, Razorpay connected, Shipping zones, catalogue and content steps; each open step has Open that goes to the right screen. | L14: Not Run | M14: High | N14: Functional | S14: Store owner | T14: No | U14: docs/qa/regression/vendor-cms/VC-02-dashboard.md
A15: VC-02-007 | B15: Vendor CMS | C15: VC-02 · Store dashboard and navigation | D15: Checklist | E15: Step ticks when done | F15: Completing a step ticks it. | G15: Signed in as Home Orbit's owner (or super admin with Manage store on Home Orbit) | H15: Save contact details (VC-03) | I15: 1. Note the checklist count 2. Complete a step 3. Reload the dashboard 4. Verify the expected result. | J15: That step is ticked and the count goes up. | L15: Not Run | M15: Medium | N15: Integration | S15: Store owner | T15: No | U15: docs/qa/regression/vendor-cms/VC-02-dashboard.md
A16: VC-02-008 | B16: Vendor CMS | C16: VC-02 · Store dashboard and navigation | D16: Figures | E16: Figures and charts | F16: Figures and charts use real orders. | G16: Signed in as Home Orbit's owner (or super admin with Manage store on Home Orbit); store selling: `pnpm demo:selling home-orbit` run; `pnpm demo:orders home-orbit` | H16: — | I16: 1. Read Orders today, Sales today, To ship, New enquiries, Low stock 2. Read Sales, last 14 days and Orders to ship 3. Verify the expected result. | J16: Figures show numbers; each figure opens its list; the chart has bars; Orders to ship lists waiting orders with Paid or COD. | L16: Not Run | M16: High | N16: Integration | S16: Store owner | T16: No | U16: docs/qa/regression/vendor-cms/VC-02-dashboard.md
A17: VC-02-009 | B17: Vendor CMS | C17: VC-02 · Store dashboard and navigation | D17: Lists | E17: Needs attention, quick actions, activity | F17: The lower cards show the store's state. | G17: Signed in as Home Orbit's owner (or super admin with Manage store on Home Orbit) | H17: — | I17: 1. Read Needs your attention, Quick actions, Recent activity, Coming up and the plan card 2. Verify the expected result. | J17: Policy pages still drafts are listed; Quick actions has Add product, Create page, Landing page, Upload media, Add category, Log an enquiry, Add dealer, Invite staff, Store settings; Recent activity shows who and when. | L17: Not Run | M17: Medium | N17: UI/UX | S17: Store owner | T17: No | U17: docs/qa/regression/vendor-cms/VC-02-dashboard.md
A18: VC-02-010 | B18: Vendor CMS | C18: VC-02 · Store dashboard and navigation | D18: Roles | E18: Dashboard follows role | F18: A catalog editor's dashboard hides what they cannot use. | G18: Signed in as a Catalog editor (VC-28) | H18: — | I18: 1. Open the dashboard 2. Verify the expected result. | J18: No launch checklist, no enquiry cards and only the quick actions they can use. | L18: Not Run | M18: High | N18: Security/Permissions | S18: Catalog editor | T18: No | U18: docs/qa/regression/vendor-cms/VC-02-dashboard.md
A19: VC-02-011 | B19: Vendor CMS | C19: VC-02 · Store dashboard and navigation | D19: Responsive | E19: Narrow screen | F19: Below 1024 px the menu opens from a button. | G19: Signed in as Home Orbit's owner (or super admin with Manage store on Home Orbit) | H19: Window 800 px wide | I19: 1. Narrow the window 2. Press ☰ 3. Verify the expected result. | J19: The menu opens over the page and closes again; nothing runs off the screen. | L19: Not Run | M19: Low | N19: UI/UX | S19: Store owner | T19: No | U19: docs/qa/regression/vendor-cms/VC-02-dashboard.md
A20: VC-03-001 | B20: Vendor CMS | C20: VC-03 · Store settings | D20: Layout | E20: Section links | F20: Settings is one page with links to each section. | G20: Signed in as Home Orbit's owner (or super admin with Manage store on Home Orbit) | H20: — | I20: 1. Open Store → Settings 2. Press Contact in the links at the top 3. Verify the expected result. | J20: Sections Branding, Contact, Grievance officer and labels, GST and invoices, Checkout and returns, Announcement bar, Policies, Search and analytics, Store status; the page scrolls to Contact. | L20: Not Run | M20: Medium | N20: UI/UX | S20: Store owner | T20: No | U20: docs/qa/regression/vendor-cms/VC-03-store-settings.md
A21: VC-03-002 | B21: Vendor CMS | C21: VC-03 · Store settings | D21: Contact | E21: Save contact and WhatsApp | F21: Contact details save and reach the store. | G21: Signed in as Home Orbit's owner (or super admin with Manage store on Home Orbit) | H21: Phone +91 98765 43210; WhatsApp 98765 43210; email care@homeorbit.example | I21: 1. Fill the Contact section 2. Save 3. Reload a product page on http://home-orbit.localhost:3000 4. Hover Ask on WhatsApp 5. Verify the expected result. | J21: "Updated successfully."; Ask on WhatsApp appears and links to https://wa.me/919876543210?text=… (91 added); /contact shows the phone and email; the footer shows them. | L21: Not Run | M21: Critical | N21: Functional | R21: Also: Integration | S21: Store owner | T21: Yes | U21: docs/qa/regression/vendor-cms/VC-03-store-settings.md
A22: VC-03-003 | B22: Vendor CMS | C22: VC-03 · Store settings | D22: Contact | E22: Invalid email | F22: An invalid contact email is refused. | G22: Signed in as Home Orbit's owner (or super admin with Manage store on Home Orbit) | H22: Email "care@" | I22: 1. Type the email 2. Save 3. Verify the expected result. | J22: Refused with an email format message. | L22: Not Run | M22: Medium | N22: Validation | S22: Store owner | T22: No | U22: docs/qa/regression/vendor-cms/VC-03-store-settings.md
A23: VC-03-004 | B23: Vendor CMS | C23: VC-03 · Store settings | D23: Grievance officer | E23: Shown on the store | F23: The grievance officer shows on contact and footer. | G23: Signed in as Home Orbit's owner (or super admin with Manage store on Home Orbit) | H23: Name Priya Shah, Director, grievance@homeorbit.example, phone | I23: 1. Fill Grievance officer and labels 2. Save 3. Open http://home-orbit.localhost:3000/contact and the footer 4. Verify the expected result. | J23: Both show the grievance officer's name, designation and contact. | L23: Not Run | M23: High | N23: Integration | S23: Store owner | T23: No | U23: docs/qa/regression/vendor-cms/VC-03-store-settings.md
A24: VC-03-005 | B24: Vendor CMS | C24: VC-03 · Store settings | D24: GST | E24: GSTIN read-only | F24: The store's GSTIN cannot be edited here. | G24: Signed in as Home Orbit's owner (or super admin with Manage store on Home Orbit) | H24: — | I24: 1. Open GST and invoices 2. Verify the expected result. | J24: GSTIN shows read-only (changed only by the platform). | L24: Not Run | M24: Medium | N24: Security/Permissions | S24: Store owner | T24: No | U24: docs/qa/regression/vendor-cms/VC-03-store-settings.md
A25: VC-03-006 | B25: Vendor CMS | C25: VC-03 · Store settings | D25: Returns | E25: Return window | F25: The return window shows on product pages. | G25: Signed in as Home Orbit's owner (or super admin with Manage store on Home Orbit); store selling: `pnpm demo:selling home-orbit` run | H25: Return window 10 days | I25: 1. Set Return window to 10 2. Save 3. Open a product on http://home-orbit.localhost:3000 4. Verify the expected result. | J25: "10-day returns" in the promises line; 0 and 91 are refused (0 to 90 allowed). | L25: Not Run | M25: Medium | N25: Integration | R25: Also: Boundary | S25: Store owner | T25: No | U25: docs/qa/regression/vendor-cms/VC-03-store-settings.md
A26: VC-03-007 | B26: Vendor CMS | C26: VC-03 · Store settings | D26: Announcement bar | E26: Store announcement | F26: The announcement bar text shows on the store when on. | G26: Signed in as Home Orbit's owner (or super admin with Manage store on Home Orbit) | H26: Text "Free delivery above ₹999", enabled | I26: 1. Fill and enable Announcement bar 2. Save 3. Reload http://home-orbit.localhost:3000 4. Verify the expected result. | J26: The text shows at the top of every store page (unless a live scheme's announcement replaces it). | L26: Not Run | M26: Medium | N26: Integration | S26: Store owner | T26: No | U26: docs/qa/regression/vendor-cms/VC-03-store-settings.md
A27: VC-03-008 | B27: Vendor CMS | C27: VC-03 · Store settings | D27: Store status | E27: Maintenance mode | F27: Maintenance mode closes the store and warns staff. | G27: Signed in as Home Orbit's owner (or super admin with Manage store on Home Orbit) | H27: Tick Maintenance mode | I27: 1. Tick Maintenance mode 2. Save 3. Open http://home-orbit.localhost:3000 4. Untick and Save 5. Verify the expected result. | J27: A yellow "Maintenance mode is on" bar on every CMS page and in Needs your attention; the store shows "Home Orbit will be back soon"; unticking reopens it. | L27: Not Run | M27: High | N27: Integration | S27: Store owner | T27: No | U27: docs/qa/regression/vendor-cms/VC-03-store-settings.md
A28: VC-03-009 | B28: Vendor CMS | C28: VC-03 · Store settings | D28: Permissions | E28: Read-only for catalog editor | F28: A catalog editor sees settings read-only. | G28: Signed in as Catalog editor | H28: — | I28: 1. Open Store → Settings 2. Verify the expected result. | J28: No Save button; fields cannot be changed. | L28: Not Run | M28: High | N28: Security/Permissions | S28: Catalog editor | T28: No | U28: docs/qa/regression/vendor-cms/VC-03-store-settings.md
A29: VC-04-001 | B29: Vendor CMS | C29: VC-04 · Products and product editor | D29: List | E29: Header, tabs and columns | F29: The product list matches the wireframe. | G29: Signed in as Home Orbit's owner (or super admin with Manage store on Home Orbit) | H29: — | I29: 1. Open Catalog → Products 2. Verify the expected result. | J29: "110 products · 500 allowed on Starter", Import, Export, Add product; tabs All, Active, Draft, Archived with counts; rows with photo, model number, category, finishes, price or range, stock, status, updated. | K29: "110 products · 500 allowed on Starter", Import, Export, Add product, tabs All 110 / Active 110 / Draft 0 / Archived 0, Category filter with subcategories. | L29: Pass | M29: High | N29: UI/UX | O29: Claude (Claude in Chrome) | P29: 2026-10-10 | S29: Store owner | T29: Yes | U29: docs/qa/regression/vendor-cms/VC-04-products.md
A30: VC-04-002 | B30: Vendor CMS | C30: VC-04 · Products and product editor | D30: List | E30: Search by model number | F30: Search finds a product by model number. | G30: Signed in as Home Orbit's owner (or super admin with Manage store on Home Orbit) | H30: HOPH-504 | I30: 1. Type HOPH-504 in the search 2. Verify the expected result. | J30: One result: the Feather pull handle. | L30: Not Run | M30: High | N30: Functional | S30: Store owner | T30: Yes | U30: docs/qa/regression/vendor-cms/VC-04-products.md
A31: VC-04-003 | B31: Vendor CMS | C31: VC-04 · Products and product editor | D31: List | E31: Search by exact SKU | F31: An exact variant SKU finds its product. | G31: Signed in as Home Orbit's owner (or super admin with Manage store on Home Orbit); variants created (VC-04-012) | H31: HOPH-504-8-INCH-ANTIQUE | I31: 1. Search the SKU 2. Verify the expected result. | J31: The parent product is listed. | L31: Not Run | M31: Medium | N31: Functional | S31: Store owner | T31: No | U31: docs/qa/regression/vendor-cms/VC-04-products.md
A32: VC-04-004 | B32: Vendor CMS | C32: VC-04 · Products and product editor | D32: List | E32: Category filter with subcategories | F32: Filtering by a parent category includes its children. | G32: Signed in as Home Orbit's owner (or super admin with Manage store on Home Orbit) | H32: Category Door hardware | I32: 1. Pick Category = Door hardware 2. Verify the expected result. | J32: 50 products from Aldrops, Pull handles, Glass door handles and Door stoppers. | L32: Not Run | M32: Medium | N32: Functional | S32: Store owner | T32: No | U32: docs/qa/regression/vendor-cms/VC-04-products.md
A33: VC-04-005 | B33: Vendor CMS | C33: VC-04 · Products and product editor | D33: List | E33: Stock filter | F33: The stock filter shows low and out-of-stock products. | G33: Signed in as Home Orbit's owner (or super admin with Manage store on Home Orbit); store selling: `pnpm demo:selling home-orbit` run | H33: Stock = Out of stock | I33: 1. Pick the stock filter 2. Verify the expected result. | J33: Only products whose variants are out of stock; an empty state when none. | L33: Not Run | M33: Low | N33: Functional | S33: Store owner | T33: No | U33: docs/qa/regression/vendor-cms/VC-04-products.md
A34: VC-04-006 | B34: Vendor CMS | C34: VC-04 · Products and product editor | D34: Bulk | E34: Publish and archive selected | F34: Bulk actions act on ticked rows and report failures. | G34: Signed in as Home Orbit's owner (or super admin with Manage store on Home Orbit) | H34: Tick two products, one without a photo | I34: 1. Tick two rows 2. Press Archive 3. Then tick them and Publish 4. Verify the expected result. | J34: Archive moves both to Archived; Publish activates the one that can and lists the other with the reason (no photo). | L34: Not Run | M34: High | N34: Functional | R34: Also: Negative | S34: Store owner | T34: No | U34: docs/qa/regression/vendor-cms/VC-04-products.md
A35: VC-04-007 | B35: Vendor CMS | C35: VC-04 · Products and product editor | D35: Bulk | E35: Change category | F35: Bulk change category moves products. | G35: Signed in as Home Orbit's owner (or super admin with Manage store on Home Orbit) | H35: Two products → Towel rings | I35: 1. Tick two products 2. Press Change category 3. Pick Towel rings and confirm 4. Verify the expected result. | J35: Both now show Towel rings as their category. | L35: Not Run | M35: Medium | N35: Functional | S35: Store owner | T35: No | U35: docs/qa/regression/vendor-cms/VC-04-products.md
A36: VC-04-008 | B36: Vendor CMS | C36: VC-04 · Products and product editor | D36: Export | E36: Export and export selected | F36: Export gives the import template's columns. | G36: Signed in as Home Orbit's owner (or super admin with Manage store on Home Orbit) | H36: — | I36: 1. Press Export 2. Tick two rows and press Export selected 3. Verify the expected result. | J36: CSVs in the template columns (with option.<axis> columns); the selected export has only those two; importing the file unchanged reports no changes. | L36: Not Run | M36: Medium | N36: Functional | R36: Also: Integration | S36: Store owner | T36: No | U36: docs/qa/regression/vendor-cms/VC-04-products.md
A37: VC-04-009 | B37: Vendor CMS | C37: VC-04 · Products and product editor | D37: Editor | E37: Sections and side column | F37: The editor has the wireframe's sections. | G37: Signed in as Home Orbit's owner (or super admin with Manage store on Home Orbit) | H37: Open HOPH-504 | I37: 1. Open the product 2. Verify the expected result. | J37: Basics, Photos and videos, Specifications, Finishes prices and stock, Price and GST, Documents, Spare parts and related products, Search engines; side: Status, How shoppers buy, Legal details, weight and box size, Featured, Offers and reviews. | L37: Not Run | M37: Medium | N37: UI/UX | S37: Store owner | T37: No | U37: docs/qa/regression/vendor-cms/VC-04-products.md
A38: VC-04-010 | B38: Vendor CMS | C38: VC-04 · Products and product editor | D38: Editor | E38: GST preview | F38: The GST split preview follows the price. | G38: Signed in as Home Orbit's owner (or super admin with Manage store on Home Orbit) | H38: Price ₹1,849, GST 18% | I38: 1. Enter the price 2. Read the line under Price and GST 3. Verify the expected result. | J38: "For ₹1,849.00 the taxable value is ₹1,566.95 and GST is ₹282.05" (prices include GST). | L38: Not Run | M38: Medium | N38: Functional | S38: Store owner | T38: No | U38: docs/qa/regression/vendor-cms/VC-04-products.md
A39: VC-04-011 | B39: Vendor CMS | C39: VC-04 · Products and product editor | D39: Editor | E39: Finish offered reaches the store | F39: Unticking a finish removes it from the store. | G39: Signed in as Home Orbit's owner (or super admin with Manage store on Home Orbit) | H39: HOPH-504: untick Black matt | I39: 1. Untick Black matt under Specifications 2. Save 3. Open the product on http://home-orbit.localhost:3000 4. Tick it again and Save 5. Verify the expected result. | J39: Black matt is gone from the finish choices, then back. | L39: Not Run | M39: High | N39: Integration | S39: Store owner | T39: No | U39: docs/qa/regression/vendor-cms/VC-04-products.md
A40: VC-04-012 | B40: Vendor CMS | C40: VC-04 · Products and product editor | D40: Variants | E40: Create variants | F40: Variants are created for every combination once. | G40: Signed in as Home Orbit's owner (or super admin with Manage store on Home Orbit) | H40: HOPH-504 with 3 sizes and 5 finishes | I40: 1. Press Create variants for every combination 2. Press it again 3. Verify the expected result. | J40: "15 variants created" with codes like HOPH-504-8-INCH-ANTIQUE; the second press says "Every combination already has a variant". | L40: Not Run | M40: High | N40: Functional | S40: Store owner | T40: No | U40: docs/qa/regression/vendor-cms/VC-04-products.md
...

Sheet Super Admin
A1: Test Case ID | B1: Application/Portal | C1: Module Name | D1: Submodule/Feature | E1: Functionality | F1: Test Scenario | G1: Preconditions | H1: Test Data | I1: Step-by-Step Instructions | J1: Expected Result | K1: Actual Result | L1: Status | M1: Priority | N1: Test Type | O1: Executed By | P1: Execution Date | Q1: Defect/Bug ID | R1: Remarks/Additional Notes | S1: Role | T1: Smoke Run | U1: Regression Script
A2: SA-01-001 | B2: Super Admin | C2: SA-01 · Sign in and two-step verification | D2: Sign in | E2: Page layout | F2: The sign-in page shows the platform form with its fields and options. | G2: Signed out | H2: — | I2: 1. Open http://localhost:3000/admin 2. Verify you are sent to the sign-in page 3. Verify the expected result. | J2: Email and Password fields, a Show control on the password, a "Keep me signed in on this device" box and a Sign in button. | K2: Email, Password with Show, Forgot password?, Keep me signed in on this device and Sign in shown. | L2: Pass | M2: Medium | N2: UI/UX | O2: Claude (Claude in Chrome) | P2: 2026-10-10 | S2: Super admin | T2: Yes | U2: docs/qa/regression/super-admin/SA-01-sign-in.md
A3: SA-01-002 | B3: Super Admin | C3: SA-01 · Sign in and two-step verification | D3: Sign in | E3: Wrong password | F3: A wrong password is refused with a message that does not say which part was wrong. | G3: Signed out | H3: Email admin@tenantecom.local; password "wrong-password-1" | I3: 1. Type the email and the wrong password 2. Press Sign in 3. Verify the expected result. | J3: The message "The email or password provided is incorrect." shows; you stay on the sign-in page. | K3: "The email or password provided is incorrect." shown; stayed on sign-in. | L3: Pass | M3: Critical | N3: Negative | O3: Claude (Claude in Chrome) | P3: 2026-10-10 | R3: First try froze while the page was still loading; typing before hydration is lost (see guide). | S3: Super admin | T3: Yes | U3: docs/qa/regression/super-admin/SA-01-sign-in.md
A4: SA-01-003 | B4: Super Admin | C4: SA-01 · Sign in and two-step verification | D4: Sign in | E4: Unknown email | F4: An email with no account gets the same message as a wrong password. | G4: Signed out | H4: Email nobody@tenantecom.local; any password | I4: 1. Type the unknown email and a password 2. Press Sign in 3. Verify the expected result. | J4: The same "The email or password provided is incorrect." message; nothing tells that the account does not exist. | L4: Not Run | M4: High | N4: Security/Permissions | S4: Super admin | T4: No | U4: docs/qa/regression/super-admin/SA-01-sign-in.md
A5: SA-01-004 | B5: Super Admin | C5: SA-01 · Sign in and two-step verification | D5: Sign in | E5: Required fields | F5: Empty fields are caught before sending. | G5: Signed out | H5: Both fields empty | I5: 1. Leave Email and Password empty 2. Press Sign in 3. Verify the expected result. | J5: The form asks for the email and the password; no request signs you in. | K5: Browser asked to fill out the email field; nothing was sent. | L5: Pass | M5: Medium | N5: Validation | O5: Claude (Claude in Chrome) | P5: 2026-10-10 | S5: Super admin | T5: No | U5: docs/qa/regression/super-admin/SA-01-sign-in.md
A6: SA-01-005 | B6: Super Admin | C6: SA-01 · Sign in and two-step verification | D6: Two-step | E6: Step 2 asked | F6: After the right password a platform account is asked for its authenticator code. | G6: Signed out; super admin has two-step set up | H6: Right email and password | I6: 1. Type the right email and password 2. Press Sign in 3. Verify the next screen 4. Verify the expected result. | J6: "Step 2 of 2, Two-step verification" with six code boxes; the dashboard is not shown yet. | K6: "Step 2 of 2, Two-step verification" with six boxes, Verify and continue, Use a different account and the lost-phone note. | L6: Pass | M6: Critical | N6: Security/Permissions | O6: Claude (Claude in Chrome) | P6: 2026-10-10 | S6: Super admin | T6: Yes | U6: docs/qa/regression/super-admin/SA-01-sign-in.md
A7: SA-01-006 | B7: Super Admin | C7: SA-01 · Sign in and two-step verification | D7: Two-step | E7: Wrong code | F7: A wrong 6-digit code is refused. | G7: On Step 2 of 2 | H7: Code 000000 (not the app's current code) | I7: 1. Type 000000 in the six boxes 2. Submit 3. Verify the expected result. | J7: The message "That code didn't work" (or similar) shows; you stay on step 2. | K7: "That code didn't work. Check the time on your phone and try the newest code."; boxes cleared. | L7: Pass | M7: Critical | N7: Negative | O7: Claude (Claude in Chrome) | P7: 2026-10-10 | S7: Super admin | T7: Yes | U7: docs/qa/regression/super-admin/SA-01-sign-in.md
A8: SA-01-007 | B8: Super Admin | C8: SA-01 · Sign in and two-step verification | D8: Two-step | E8: Right code, paste | F8: The authenticator code signs you in; pasting all six digits into the first box fills them all. | G8: On Step 2 of 2 | H8: The current code from the authenticator app | I8: 1. Copy the 6-digit code 2. Paste it into the first box 3. Verify all six boxes are filled 4. Submit if it does not submit by itself 5. Verify the expected result. | J8: You land on the platform dashboard, "Good morning/afternoon/evening, Platform". | K8: Typing the authenticator code submitted at the sixth digit and opened "Good morning, Platform". | L8: Pass | M8: Critical | N8: Functional | O8: Claude (Claude in Chrome) | P8: 2026-10-10 | R8: Paste into the first box is handled in code (CodeBoxes onPaste); a synthetic paste from the extension does not insert text, so paste needs a human check. | S8: Super admin | T8: Yes | U8: docs/qa/regression/super-admin/SA-01-sign-in.md
A9: SA-01-008 | B9: Super Admin | C9: SA-01 · Sign in and two-step verification | D9: Two-step | E9: First-time setup | F9: A platform account without two-step sees only the setup until it is done. | G9: A new Support teammate (SA-14) signed in for the first time | H9: Their email and password; an authenticator app | I9: 1. Sign in as the new teammate 2. Verify the panel is covered by "Set up two-step sign-in" 3. Press it, scan the QR code (or type the setup key) 4. Type the app's 6-digit code and confirm 5. Verify the dashboard shows 6. Verify the expected result. | J9: Until the code is confirmed, no platform screen is usable; after it, the dashboard shows and Team and access lists Two-step On. | L9: Not Run | M9: Critical | N9: Security/Permissions | S9: Super admin | T9: No | U9: docs/qa/regression/super-admin/SA-01-sign-in.md
A10: SA-01-009 | B10: Super Admin | C10: SA-01 · Sign in and two-step verification | D10: Two-step | E10: Setup with a wrong code | F10: Two-step setup is not saved with a wrong confirmation code. | G10: On the setup screen | H10: Code 123456 that the app did not show | I10: 1. Type a wrong code on the setup screen 2. Confirm 3. Verify the expected result. | J10: An error says the code did not match; two-step stays off and the setup screen stays. | L10: Not Run | M10: High | N10: Negative | S10: Super admin | T10: No | U10: docs/qa/regression/super-admin/SA-01-sign-in.md
A11: SA-01-010 | B11: Super Admin | C11: SA-01 · Sign in and two-step verification | D11: Sessions | E11: Keep me signed in | F11: Without the tick the session ends with the browser; with it, it survives a restart (8 hours at most). | G11: Signed out | H11: Right credentials and code | I11: 1. Sign in without ticking "Keep me signed in on this device" 2. Close every browser window and reopen the admin 3. Verify you must sign in again 4. Sign in again with the box ticked 5. Close and reopen the browser 6. Verify you are still signed in 7. Verify the expected result. | J11: Unticked: signed out after the browser closes. Ticked: still signed in after reopening. | L11: Not Run | M11: Medium | N11: Data persistence | S11: Super admin | T11: No | U11: docs/qa/regression/super-admin/SA-01-sign-in.md
A12: SA-01-011 | B12: Super Admin | C12: SA-01 · Sign in and two-step verification | D12: Sessions | E12: Sign out | F12: Signing out ends the session. | G12: Signed in | H12: — | I12: 1. Open the account menu and sign out 2. Open http://localhost:3000/admin 3. Verify the expected result. | J12: The sign-in page shows; the browser back button does not reopen admin data. | L12: Not Run | M12: High | N12: Security/Permissions | S12: Super admin | T12: Yes | U12: docs/qa/regression/super-admin/SA-01-sign-in.md
A13: SA-01-012 | B13: Super Admin | C13: SA-01 · Sign in and two-step verification | D13: Lockout | E13: Five wrong passwords | F13: Five wrong passwords lock the account for 15 minutes. | G13: Use a store owner that does not matter (owner@demo-clothing.example), private window | H13: Wrong password 6 times | I13: 1. Sign in with a wrong password 5 times; read the message each time 2. Try a 6th time 3. Verify the expected result. | J13: Tries 1–5: "The email or password provided is incorrect." The 6th: "This user is locked due to having too many failed login attempts." It lifts after 15 minutes. | L13: Not Run | M13: High | N13: Security/Permissions | R13: Also: Boundary | S13: Tester (any) | T13: No | U13: docs/qa/regression/super-admin/SA-01-sign-in.md
A14: SA-01-013 | B14: Super Admin | C14: SA-01 · Sign in and two-step verification | D14: Lockout | E14: Wrong codes | F14: Repeated wrong two-step codes lock sign-in like wrong passwords. | G14: On Step 2 of 2 for a test platform account (not your only super admin) | H14: 5 wrong codes | I14: 1. Type a wrong code 5 times 2. Then type the right code 3. Verify the expected result. | J14: After 5 wrong codes the account is locked for 15 minutes and even the right code is refused until then. | L14: Not Run | M14: Medium | N14: Security/Permissions | R14: Use a throw-away Support account so you are not locked out.; Also: Boundary | S14: Super admin | T14: No | U14: docs/qa/regression/super-admin/SA-01-sign-in.md
A15: SA-01-014 | B15: Super Admin | C15: SA-01 · Sign in and two-step verification | D15: Password reset | E15: Forgot password | F15: The reset link sets a new password; a too-short one is refused. | G15: Signed out; a test account | H15: New password "short1" then a 10+ character one | I15: 1. Use Forgot password with the account's email 2. Open the link printed in the `pnpm dev` terminal ([dev-log email]) 3. Try "short1" 4. Then a 10-character or longer password 5. Verify the expected result. | J15: Short passwords are refused (10 characters at least); a valid one saves and the account signs in with it (still asking for the code when two-step is on). | L15: Not Run | M15: High | N15: Validation | S15: Super admin | T15: No | U15: docs/qa/regression/super-admin/SA-01-sign-in.md
A16: SA-02-001 | B16: Super Admin | C16: SA-02 · Platform dashboard | D16: Figures | E16: Tiles | F16: The five figures show as the wireframe. | G16: Signed in as super admin | H16: Seeded QA data | I16: 1. Open http://localhost:3000/admin 2. Read the figure tiles 3. Verify the expected result. | J16: Live stores, MRR (before GST), Past due, Orders today (all stores) and GMV this month are shown with numbers. | K16: Live stores 2 (1 paying, 1 on trial), MRR ₹6,999 before GST, Past due 0, Orders today 1, GMV October ₹25,273. | L16: Pass | M16: High | N16: UI/UX | O16: Claude (Claude in Chrome) | P16: 2026-10-10 | S16: Super admin | T16: Yes | U16: docs/qa/regression/super-admin/SA-02-dashboard.md
A17: SA-02-002 | B17: Super Admin | C17: SA-02 · Platform dashboard | D17: Figures | E17: Live stores count | F17: Live stores counts active stores only. | G17: Two active stores and Home Orbit as a draft | H17: — | I17: 1. Read Live stores 2. Compare with All vendors → Active tab count 3. Verify the expected result. | J17: Live stores equals the Active count (2 on a fresh seed; 3 after Home Orbit goes live). | L17: Not Run | M17: High | N17: Integration | S17: Super admin | T17: No | U17: docs/qa/regression/super-admin/SA-02-dashboard.md
A18: SA-02-003 | B18: Super Admin | C18: SA-02 · Platform dashboard | D18: Sales | E18: Sales across all stores | F18: The chart has one bar per day of the month and reflects orders. | G18: Demo orders created for Home Orbit | H18: `pnpm demo:orders home-orbit` | I18: 1. Read the Sales across all stores chart 2. Hover or compare bars with Top stores 3. Verify the expected result. | J18: Bars appear on days with sold orders; days without orders are empty; the month total matches GMV this month. | L18: Not Run | M18: Medium | N18: Integration | S18: Super admin | T18: No | U18: docs/qa/regression/super-admin/SA-02-dashboard.md
A19: SA-02-004 | B19: Super Admin | C19: SA-02 · Platform dashboard | D19: Lists | E19: Top stores this month | F19: Stores with orders are ranked by GMV. | G19: Demo orders exist | H19: — | I19: 1. Read Top stores this month 2. Verify the expected result. | J19: Each row shows vendor, industry, orders, GMV and the change against last month to the same day; Home Orbit is listed. | K19: Top stores: Home Orbit, Door and furniture hardware, Home decor, 8 orders, ₹25,273, New. | L19: Pass | M19: Medium | N19: Functional | O19: Claude (Claude in Chrome) | P19: 2026-10-10 | S19: Super admin | T19: No | U19: docs/qa/regression/super-admin/SA-02-dashboard.md
A20: SA-02-005 | B20: Super Admin | C20: SA-02 · Platform dashboard | D20: Lists | E20: Needs attention | F20: Stores needing action are listed with the reason. | G20: Fresh seed | H20: — | I20: 1. Read Needs attention 2. Verify the expected result. | J20: Home Orbit "Store is still a draft" and the owners who have not accepted their invite are listed; each row opens the vendor. | K20: Home Orbit "Store is still a draft" and three owners who have not accepted their invite. | L20: Pass | M20: High | N20: Functional | O20: Claude (Claude in Chrome) | P20: 2026-10-10 | S20: Super admin | T20: No | U20: docs/qa/regression/super-admin/SA-02-dashboard.md
A21: SA-02-006 | B21: Super Admin | C21: SA-02 · Platform dashboard | D21: Lists | E21: Recently onboarded with Resend invite | F21: Recently created stores show with status; Resend invite sends a new link. | G21: Fresh seed | H21: — | I21: 1. Read Recently onboarded 2. Press Resend invite on a store whose owner has not accepted 3. Watch the `pnpm dev` terminal 4. Verify the expected result. | J21: Home Orbit (Draft), Demo Clothing and Demo Sanitary (Active) show; Resend invite prints a [dev-log email] with a set-password link. | L21: Not Run | M21: Medium | N21: Integration | S21: Super admin | T21: No | U21: docs/qa/regression/super-admin/SA-02-dashboard.md
A22: SA-02-007 | B22: Super Admin | C22: SA-02 · Platform dashboard | D22: Navigation | E22: Platform menu | F22: The left menu has only platform sections. | G22: Signed in as super admin, no store session | H22: — | I22: 1. Read the left menu 2. Verify the expected result. | J22: Dashboard; Vendors (All vendors, New vendor); Billing (Plans, Subscriptions); Platform (Team and access, Staff users). No store sections such as Products or Orders. | K22: Menu: Dashboard, All vendors, New vendor, Plans, Subscriptions, Team and access, Staff users; no store sections. | L22: Pass | M22: High | N22: UI/UX | O22: Claude (Claude in Chrome) | P22: 2026-10-10 | R22: Also: Security/Permissions | S22: Super admin | T22: Yes | U22: docs/qa/regression/super-admin/SA-02-dashboard.md
A23: SA-02-008 | B23: Super Admin | C23: SA-02 · Platform dashboard | D23: Gate | E23: Two-step gate | F23: A platform account without two-step sees the setup in place of the menu. | G23: A Support teammate who has not set up two-step | H23: — | I23: 1. Sign in as that teammate 2. Try to open All vendors from the address bar 3. Verify the expected result. | J23: The panel shows only "Set up two-step sign-in"; no vendor data is shown until it is done. | L23: Not Run | M23: High | N23: Security/Permissions | S23: Super admin | T23: No | U23: docs/qa/regression/super-admin/SA-02-dashboard.md
